2025-09-20 18:55:14,177 - models.lstm_health_model - ERROR - lstm_health_model.py:302 - Error loading model: [Errno 2] Unable to synchronously open file (unable to open file: name = './models/lstm_health_model.h5', errno = 2, error message = 'No such file or directory', flags = 0, o_flags = 0)
2025-09-20 18:55:14,180 - models.transformer_genomic_model - ERROR - transformer_genomic_model.py:418 - Error loading model: [Errno 2] Unable to synchronously open file (unable to open file: name = './models/transformer_genomic_model.h5', errno = 2, error message = 'No such file or directory', flags = 0, o_flags = 0)
2025-09-20 18:55:15,419 - models.ai_models - ERROR - ai_models.py:196 - Error during training: Training data contains 0 samples, which is not sufficient to split it into a validation and training set as specified by `validation_split=0.2`. Either provide more data, or a different value for the `validation_split` argument.
2025-09-20 18:58:30,359 - models.lstm_health_model - ERROR - lstm_health_model.py:330 - Error loading model: [Errno 2] Unable to synchronously open file (unable to open file: name = './models/lstm_health_model.h5', errno = 2, error message = 'No such file or directory', flags = 0, o_flags = 0)
2025-09-20 18:58:30,361 - models.transformer_genomic_model - ERROR - transformer_genomic_model.py:418 - Error loading model: [Errno 2] Unable to synchronously open file (unable to open file: name = './models/transformer_genomic_model.h5', errno = 2, error message = 'No such file or directory', flags = 0, o_flags = 0)
2025-09-20 18:58:31,590 - models.ai_models - ERROR - ai_models.py:196 - Error during training: No valid sequences could be created from the data
2025-09-20 18:58:31,590 - __main__ - ERROR - train_models.py:293 - Error during model training: No valid sequences could be created from the data
2025-09-20 19:05:45,489 - models.lstm_health_model - ERROR - lstm_health_model.py:338 - Error loading model: [Errno 2] Unable to synchronously open file (unable to open file: name = './models/lstm_health_model.h5', errno = 2, error message = 'No such file or directory', flags = 0, o_flags = 0)
2025-09-20 19:05:45,490 - models.transformer_genomic_model - ERROR - transformer_genomic_model.py:418 - Error loading model: [Errno 2] Unable to synchronously open file (unable to open file: name = './models/transformer_genomic_model.h5', errno = 2, error message = 'No such file or directory', flags = 0, o_flags = 0)
2025-09-20 19:05:45,928 - models.ai_models - ERROR - ai_models.py:200 - Error during training: Input 0 of layer "functional" is incompatible with the layer: expected shape=(None, 30, 10), found shape=(32, 30, 12)
2025-09-20 19:05:45,929 - __main__ - ERROR - train_models.py:293 - Error during model training: Input 0 of layer "functional" is incompatible with the layer: expected shape=(None, 30, 10), found shape=(32, 30, 12)
2025-09-20 19:07:35,049 - models.lstm_health_model - ERROR - lstm_health_model.py:338 - Error loading model: [Errno 2] Unable to synchronously open file (unable to open file: name = './models/lstm_health_model.h5', errno = 2, error message = 'No such file or directory', flags = 0, o_flags = 0)
2025-09-20 19:07:35,050 - models.transformer_genomic_model - ERROR - transformer_genomic_model.py:418 - Error loading model: [Errno 2] Unable to synchronously open file (unable to open file: name = './models/transformer_genomic_model.h5', errno = 2, error message = 'No such file or directory', flags = 0, o_flags = 0)
2025-09-20 19:07:36,348 - models.ai_models - ERROR - ai_models.py:200 - Error during training: Arguments `target` and `output` must have the same rank (ndim). Received: target.shape=(32,), output.shape=(32, 8)
2025-09-20 19:07:36,349 - __main__ - ERROR - train_models.py:293 - Error during model training: Arguments `target` and `output` must have the same rank (ndim). Received: target.shape=(32,), output.shape=(32, 8)
2025-09-20 19:40:56,926 - models.lstm_health_model - ERROR - lstm_health_model.py:338 - Error loading model: [Errno 2] Unable to synchronously open file (unable to open file: name = './models/lstm_health_model.h5', errno = 2, error message = 'No such file or directory', flags = 0, o_flags = 0)
2025-09-20 19:40:56,926 - models.transformer_genomic_model - ERROR - transformer_genomic_model.py:418 - Error loading model: [Errno 2] Unable to synchronously open file (unable to open file: name = './models/transformer_genomic_model.h5', errno = 2, error message = 'No such file or directory', flags = 0, o_flags = 0)
2025-09-20 19:41:33,245 - models.ai_models - ERROR - ai_models.py:200 - Error during training: Arguments `target` and `output` must have the same rank (ndim). Received: target.shape=(32,), output.shape=(32, 6)
2025-09-20 19:41:33,245 - __main__ - ERROR - train_models.py:293 - Error during model training: Arguments `target` and `output` must have the same rank (ndim). Received: target.shape=(32,), output.shape=(32, 6)
2025-09-20 19:44:34,521 - models.lstm_health_model - ERROR - lstm_health_model.py:338 - Error loading model: Could not deserialize 'keras.metrics.mse' because it is not a KerasSaveable subclass
2025-09-20 19:44:34,523 - models.transformer_genomic_model - ERROR - transformer_genomic_model.py:418 - Error loading model: [Errno 2] Unable to synchronously open file (unable to open file: name = './models/transformer_genomic_model.h5', errno = 2, error message = 'No such file or directory', flags = 0, o_flags = 0)
2025-09-20 20:04:55,349 - models.lstm_health_model - ERROR - lstm_health_model.py:338 - Error loading model: Could not deserialize 'keras.metrics.mse' because it is not a KerasSaveable subclass
2025-09-20 20:04:55,351 - models.transformer_genomic_model - ERROR - transformer_genomic_model.py:418 - Error loading model: [Errno 2] Unable to synchronously open file (unable to open file: name = './models/transformer_genomic_model.h5', errno = 2, error message = 'No such file or directory', flags = 0, o_flags = 0)
2025-09-20 20:15:44,226 - models.lstm_health_model - ERROR - lstm_health_model.py:338 - Error loading model: Could not deserialize 'keras.metrics.mse' because it is not a KerasSaveable subclass
2025-09-20 20:15:44,227 - models.transformer_genomic_model - ERROR - transformer_genomic_model.py:418 - Error loading model: [Errno 2] Unable to synchronously open file (unable to open file: name = './models/transformer_genomic_model.h5', errno = 2, error message = 'No such file or directory', flags = 0, o_flags = 0)
2025-09-20 20:54:03,923 - models.lstm_health_model - ERROR - lstm_health_model.py:338 - Error loading model: Could not deserialize 'keras.metrics.mse' because it is not a KerasSaveable subclass
2025-09-20 20:54:03,926 - models.transformer_genomic_model - ERROR - transformer_genomic_model.py:418 - Error loading model: [Errno 2] Unable to synchronously open file (unable to open file: name = './models/transformer_genomic_model.h5', errno = 2, error message = 'No such file or directory', flags = 0, o_flags = 0)
