2025-09-20 18:54:59,241 - __main__ - INFO - train_models.py:39 - Generating health data for 2000 users...
2025-09-20 18:55:01,012 - __main__ - INFO - train_models.py:95 - Generated 119969 health data points
2025-09-20 18:55:01,033 - __main__ - INFO - train_models.py:100 - Generating genomic data for 2000 users...
2025-09-20 18:55:01,336 - __main__ - INFO - train_models.py:134 - Generated genomic data for 2000 users
2025-09-20 18:55:01,338 - __main__ - INFO - train_models.py:139 - Generating mental health data for 2000 users...
2025-09-20 18:55:01,382 - __main__ - INFO - train_models.py:166 - Generated mental health data for 2000 users
2025-09-20 18:55:01,386 - __main__ - INFO - train_models.py:172 - Generating nutrition labels...
2025-09-20 18:55:12,711 - __main__ - INFO - train_models.py:239 - Generated labels for 2000 users
2025-09-20 18:55:14,176 - models.ai_models - INFO - ai_models.py:38 - Loading AI models...
2025-09-20 18:55:14,177 - models.lstm_health_model - ERROR - lstm_health_model.py:302 - Error loading model: [Errno 2] Unable to synchronously open file (unable to open file: name = './models/lstm_health_model.h5', errno = 2, error message = 'No such file or directory', flags = 0, o_flags = 0)
2025-09-20 18:55:14,177 - models.ai_models - WARNING - ai_models.py:64 - Could not load LSTM model: [Errno 2] Unable to synchronously open file (unable to open file: name = './models/lstm_health_model.h5', errno = 2, error message = 'No such file or directory', flags = 0, o_flags = 0). Will need training.
2025-09-20 18:55:14,180 - models.transformer_genomic_model - ERROR - transformer_genomic_model.py:418 - Error loading model: [Errno 2] Unable to synchronously open file (unable to open file: name = './models/transformer_genomic_model.h5', errno = 2, error message = 'No such file or directory', flags = 0, o_flags = 0)
2025-09-20 18:55:14,183 - models.ai_models - WARNING - ai_models.py:70 - Could not load Transformer model: [Errno 2] Unable to synchronously open file (unable to open file: name = './models/transformer_genomic_model.h5', errno = 2, error message = 'No such file or directory', flags = 0, o_flags = 0). Will need training.
2025-09-20 18:55:14,183 - models.ai_models - INFO - ai_models.py:90 - Model loading completed
2025-09-20 18:55:14,187 - models.ai_models - INFO - ai_models.py:119 - Starting comprehensive model training...
2025-09-20 18:55:14,187 - models.ai_models - INFO - ai_models.py:122 - Training LSTM health model...
2025-09-20 18:55:14,206 - models.lstm_health_model - INFO - lstm_health_model.py:181 - Preparing training data...
2025-09-20 18:55:15,418 - models.lstm_health_model - INFO - lstm_health_model.py:189 - Model architecture:
None
2025-09-20 18:55:15,418 - models.lstm_health_model - INFO - lstm_health_model.py:198 - Starting model training...
2025-09-20 18:55:15,419 - models.ai_models - ERROR - ai_models.py:196 - Error during training: Training data contains 0 samples, which is not sufficient to split it into a validation and training set as specified by `validation_split=0.2`. Either provide more data, or a different value for the `validation_split` argument.
2025-09-20 18:58:10,920 - __main__ - INFO - train_models.py:244 - Starting AI Model Training for Diet Recommendation System
2025-09-20 18:58:10,920 - __main__ - INFO - train_models.py:248 - Generating synthetic training data...
2025-09-20 18:58:10,920 - __main__ - INFO - train_models.py:39 - Generating health data for 2000 users...
2025-09-20 18:58:13,404 - __main__ - INFO - train_models.py:95 - Generated 119969 health data points
2025-09-20 18:58:13,427 - __main__ - INFO - train_models.py:100 - Generating genomic data for 2000 users...
2025-09-20 18:58:13,823 - __main__ - INFO - train_models.py:134 - Generated genomic data for 2000 users
2025-09-20 18:58:13,824 - __main__ - INFO - train_models.py:139 - Generating mental health data for 2000 users...
2025-09-20 18:58:13,880 - __main__ - INFO - train_models.py:166 - Generated mental health data for 2000 users
2025-09-20 18:58:13,881 - __main__ - INFO - train_models.py:172 - Generating nutrition labels...
2025-09-20 18:58:28,585 - __main__ - INFO - train_models.py:239 - Generated labels for 2000 users
2025-09-20 18:58:30,358 - __main__ - INFO - train_models.py:267 - Training datasets saved successfully
2025-09-20 18:58:30,358 - __main__ - INFO - train_models.py:270 - Initializing AI Model Manager...
2025-09-20 18:58:30,358 - models.ai_models - INFO - ai_models.py:38 - Loading AI models...
2025-09-20 18:58:30,359 - models.lstm_health_model - ERROR - lstm_health_model.py:330 - Error loading model: [Errno 2] Unable to synchronously open file (unable to open file: name = './models/lstm_health_model.h5', errno = 2, error message = 'No such file or directory', flags = 0, o_flags = 0)
2025-09-20 18:58:30,361 - models.ai_models - WARNING - ai_models.py:64 - Could not load LSTM model: [Errno 2] Unable to synchronously open file (unable to open file: name = './models/lstm_health_model.h5', errno = 2, error message = 'No such file or directory', flags = 0, o_flags = 0). Will need training.
2025-09-20 18:58:30,361 - models.transformer_genomic_model - ERROR - transformer_genomic_model.py:418 - Error loading model: [Errno 2] Unable to synchronously open file (unable to open file: name = './models/transformer_genomic_model.h5', errno = 2, error message = 'No such file or directory', flags = 0, o_flags = 0)
2025-09-20 18:58:30,361 - models.ai_models - WARNING - ai_models.py:70 - Could not load Transformer model: [Errno 2] Unable to synchronously open file (unable to open file: name = './models/transformer_genomic_model.h5', errno = 2, error message = 'No such file or directory', flags = 0, o_flags = 0). Will need training.
2025-09-20 18:58:30,362 - models.ai_models - INFO - ai_models.py:90 - Model loading completed
2025-09-20 18:58:30,362 - __main__ - INFO - train_models.py:275 - Starting model training...
2025-09-20 18:58:30,362 - models.ai_models - INFO - ai_models.py:119 - Starting comprehensive model training...
2025-09-20 18:58:30,362 - models.ai_models - INFO - ai_models.py:122 - Training LSTM health model...
2025-09-20 18:58:30,379 - models.lstm_health_model - INFO - lstm_health_model.py:209 - Preparing training data...
2025-09-20 18:58:31,590 - models.ai_models - ERROR - ai_models.py:196 - Error during training: No valid sequences could be created from the data
2025-09-20 18:58:31,590 - __main__ - ERROR - train_models.py:293 - Error during model training: No valid sequences could be created from the data
2025-09-20 19:05:25,586 - __main__ - INFO - train_models.py:244 - Starting AI Model Training for Diet Recommendation System
2025-09-20 19:05:25,587 - __main__ - INFO - train_models.py:248 - Generating synthetic training data...
2025-09-20 19:05:25,587 - __main__ - INFO - train_models.py:39 - Generating health data for 2000 users...
2025-09-20 19:05:27,922 - __main__ - INFO - train_models.py:95 - Generated 119969 health data points
2025-09-20 19:05:27,942 - __main__ - INFO - train_models.py:100 - Generating genomic data for 2000 users...
2025-09-20 19:05:28,329 - __main__ - INFO - train_models.py:134 - Generated genomic data for 2000 users
2025-09-20 19:05:28,330 - __main__ - INFO - train_models.py:139 - Generating mental health data for 2000 users...
2025-09-20 19:05:28,390 - __main__ - INFO - train_models.py:166 - Generated mental health data for 2000 users
2025-09-20 19:05:28,391 - __main__ - INFO - train_models.py:172 - Generating nutrition labels...
2025-09-20 19:05:43,376 - __main__ - INFO - train_models.py:239 - Generated labels for 2000 users
2025-09-20 19:05:45,487 - __main__ - INFO - train_models.py:267 - Training datasets saved successfully
2025-09-20 19:05:45,487 - __main__ - INFO - train_models.py:270 - Initializing AI Model Manager...
2025-09-20 19:05:45,488 - models.ai_models - INFO - ai_models.py:38 - Loading AI models...
2025-09-20 19:05:45,489 - models.lstm_health_model - ERROR - lstm_health_model.py:338 - Error loading model: [Errno 2] Unable to synchronously open file (unable to open file: name = './models/lstm_health_model.h5', errno = 2, error message = 'No such file or directory', flags = 0, o_flags = 0)
2025-09-20 19:05:45,490 - models.ai_models - WARNING - ai_models.py:64 - Could not load LSTM model: [Errno 2] Unable to synchronously open file (unable to open file: name = './models/lstm_health_model.h5', errno = 2, error message = 'No such file or directory', flags = 0, o_flags = 0). Will need training.
2025-09-20 19:05:45,490 - models.transformer_genomic_model - ERROR - transformer_genomic_model.py:418 - Error loading model: [Errno 2] Unable to synchronously open file (unable to open file: name = './models/transformer_genomic_model.h5', errno = 2, error message = 'No such file or directory', flags = 0, o_flags = 0)
2025-09-20 19:05:45,490 - models.ai_models - WARNING - ai_models.py:70 - Could not load Transformer model: [Errno 2] Unable to synchronously open file (unable to open file: name = './models/transformer_genomic_model.h5', errno = 2, error message = 'No such file or directory', flags = 0, o_flags = 0). Will need training.
2025-09-20 19:05:45,490 - models.ai_models - INFO - ai_models.py:90 - Model loading completed
2025-09-20 19:05:45,490 - __main__ - INFO - train_models.py:275 - Starting model training...
2025-09-20 19:05:45,492 - models.ai_models - INFO - ai_models.py:119 - Starting comprehensive model training...
2025-09-20 19:05:45,492 - models.ai_models - INFO - ai_models.py:122 - Training LSTM health model...
2025-09-20 19:05:45,507 - models.ai_models - INFO - ai_models.py:132 - Prepared training data with 2000 samples
2025-09-20 19:05:45,508 - models.lstm_health_model - INFO - lstm_health_model.py:217 - Preparing training data...
2025-09-20 19:05:45,508 - models.lstm_health_model - INFO - lstm_health_model.py:147 - Training data shape: (2000, 17)
2025-09-20 19:05:45,509 - models.lstm_health_model - INFO - lstm_health_model.py:148 - Feature columns: ['age', 'gender', 'height', 'weight', 'bmi', 'cholesterol_total', 'cholesterol_hdl', 'cholesterol_ldl', 'blood_pressure_systolic', 'blood_pressure_diastolic', 'glucose', 'triglycerides']
2025-09-20 19:05:45,509 - models.lstm_health_model - INFO - lstm_health_model.py:149 - Target columns: ['nutrition_category', 'health_risk', 'metabolic_rate', 'caloric_needs']
2025-09-20 19:05:45,509 - models.lstm_health_model - INFO - lstm_health_model.py:150 - Has timestamp: False
2025-09-20 19:05:45,608 - models.lstm_health_model - INFO - lstm_health_model.py:184 - Created 2000 sequences
2025-09-20 19:05:45,612 - models.lstm_health_model - INFO - lstm_health_model.py:190 - Final X_sequences shape: (2000, 30, 12)
2025-09-20 19:05:45,829 - models.lstm_health_model - INFO - lstm_health_model.py:225 - Model architecture:
None
2025-09-20 19:05:45,829 - models.lstm_health_model - INFO - lstm_health_model.py:234 - Starting model training...
2025-09-20 19:05:45,928 - models.ai_models - ERROR - ai_models.py:200 - Error during training: Input 0 of layer "functional" is incompatible with the layer: expected shape=(None, 30, 10), found shape=(32, 30, 12)
2025-09-20 19:05:45,929 - __main__ - ERROR - train_models.py:293 - Error during model training: Input 0 of layer "functional" is incompatible with the layer: expected shape=(None, 30, 10), found shape=(32, 30, 12)
2025-09-20 19:07:19,487 - __main__ - INFO - train_models.py:244 - Starting AI Model Training for Diet Recommendation System
2025-09-20 19:07:19,488 - __main__ - INFO - train_models.py:248 - Generating synthetic training data...
2025-09-20 19:07:19,488 - __main__ - INFO - train_models.py:39 - Generating health data for 2000 users...
2025-09-20 19:07:21,246 - __main__ - INFO - train_models.py:95 - Generated 119969 health data points
2025-09-20 19:07:21,264 - __main__ - INFO - train_models.py:100 - Generating genomic data for 2000 users...
2025-09-20 19:07:21,552 - __main__ - INFO - train_models.py:134 - Generated genomic data for 2000 users
2025-09-20 19:07:21,552 - __main__ - INFO - train_models.py:139 - Generating mental health data for 2000 users...
2025-09-20 19:07:21,599 - __main__ - INFO - train_models.py:166 - Generated mental health data for 2000 users
2025-09-20 19:07:21,600 - __main__ - INFO - train_models.py:172 - Generating nutrition labels...
2025-09-20 19:07:33,374 - __main__ - INFO - train_models.py:239 - Generated labels for 2000 users
2025-09-20 19:07:35,046 - __main__ - INFO - train_models.py:267 - Training datasets saved successfully
2025-09-20 19:07:35,047 - __main__ - INFO - train_models.py:270 - Initializing AI Model Manager...
2025-09-20 19:07:35,047 - models.ai_models - INFO - ai_models.py:38 - Loading AI models...
2025-09-20 19:07:35,049 - models.lstm_health_model - ERROR - lstm_health_model.py:338 - Error loading model: [Errno 2] Unable to synchronously open file (unable to open file: name = './models/lstm_health_model.h5', errno = 2, error message = 'No such file or directory', flags = 0, o_flags = 0)
2025-09-20 19:07:35,049 - models.ai_models - WARNING - ai_models.py:64 - Could not load LSTM model: [Errno 2] Unable to synchronously open file (unable to open file: name = './models/lstm_health_model.h5', errno = 2, error message = 'No such file or directory', flags = 0, o_flags = 0). Will need training.
2025-09-20 19:07:35,050 - models.transformer_genomic_model - ERROR - transformer_genomic_model.py:418 - Error loading model: [Errno 2] Unable to synchronously open file (unable to open file: name = './models/transformer_genomic_model.h5', errno = 2, error message = 'No such file or directory', flags = 0, o_flags = 0)
2025-09-20 19:07:35,051 - models.ai_models - WARNING - ai_models.py:70 - Could not load Transformer model: [Errno 2] Unable to synchronously open file (unable to open file: name = './models/transformer_genomic_model.h5', errno = 2, error message = 'No such file or directory', flags = 0, o_flags = 0). Will need training.
2025-09-20 19:07:35,051 - models.ai_models - INFO - ai_models.py:90 - Model loading completed
2025-09-20 19:07:35,052 - __main__ - INFO - train_models.py:275 - Starting model training...
2025-09-20 19:07:35,052 - models.ai_models - INFO - ai_models.py:119 - Starting comprehensive model training...
2025-09-20 19:07:35,052 - models.ai_models - INFO - ai_models.py:122 - Training LSTM health model...
2025-09-20 19:07:35,071 - models.ai_models - INFO - ai_models.py:132 - Prepared training data with 2000 samples
2025-09-20 19:07:35,072 - models.lstm_health_model - INFO - lstm_health_model.py:217 - Preparing training data...
2025-09-20 19:07:35,072 - models.lstm_health_model - INFO - lstm_health_model.py:147 - Training data shape: (2000, 17)
2025-09-20 19:07:35,073 - models.lstm_health_model - INFO - lstm_health_model.py:148 - Feature columns: ['age', 'gender', 'height', 'weight', 'bmi', 'cholesterol_total', 'cholesterol_hdl', 'cholesterol_ldl', 'blood_pressure_systolic', 'blood_pressure_diastolic', 'glucose', 'triglycerides']
2025-09-20 19:07:35,073 - models.lstm_health_model - INFO - lstm_health_model.py:149 - Target columns: ['nutrition_category', 'health_risk', 'metabolic_rate', 'caloric_needs']
2025-09-20 19:07:35,073 - models.lstm_health_model - INFO - lstm_health_model.py:150 - Has timestamp: False
2025-09-20 19:07:35,185 - models.lstm_health_model - INFO - lstm_health_model.py:184 - Created 2000 sequences
2025-09-20 19:07:35,188 - models.lstm_health_model - INFO - lstm_health_model.py:190 - Final X_sequences shape: (2000, 30, 12)
2025-09-20 19:07:35,373 - models.lstm_health_model - INFO - lstm_health_model.py:225 - Model architecture:
None
2025-09-20 19:07:35,373 - models.lstm_health_model - INFO - lstm_health_model.py:234 - Starting model training...
2025-09-20 19:07:36,348 - models.ai_models - ERROR - ai_models.py:200 - Error during training: Arguments `target` and `output` must have the same rank (ndim). Received: target.shape=(32,), output.shape=(32, 8)
2025-09-20 19:07:36,349 - __main__ - ERROR - train_models.py:293 - Error during model training: Arguments `target` and `output` must have the same rank (ndim). Received: target.shape=(32,), output.shape=(32, 8)
2025-09-20 19:40:39,940 - __main__ - INFO - train_models.py:244 - Starting AI Model Training for Diet Recommendation System
2025-09-20 19:40:39,940 - __main__ - INFO - train_models.py:248 - Generating synthetic training data...
2025-09-20 19:40:39,940 - __main__ - INFO - train_models.py:39 - Generating health data for 2000 users...
2025-09-20 19:40:41,758 - __main__ - INFO - train_models.py:95 - Generated 119969 health data points
2025-09-20 19:40:41,778 - __main__ - INFO - train_models.py:100 - Generating genomic data for 2000 users...
2025-09-20 19:40:42,099 - __main__ - INFO - train_models.py:134 - Generated genomic data for 2000 users
2025-09-20 19:40:42,099 - __main__ - INFO - train_models.py:139 - Generating mental health data for 2000 users...
2025-09-20 19:40:42,146 - __main__ - INFO - train_models.py:166 - Generated mental health data for 2000 users
2025-09-20 19:40:42,147 - __main__ - INFO - train_models.py:172 - Generating nutrition labels...
2025-09-20 19:40:55,244 - __main__ - INFO - train_models.py:239 - Generated labels for 2000 users
2025-09-20 19:40:56,924 - __main__ - INFO - train_models.py:267 - Training datasets saved successfully
2025-09-20 19:40:56,924 - __main__ - INFO - train_models.py:270 - Initializing AI Model Manager...
2025-09-20 19:40:56,925 - models.ai_models - INFO - ai_models.py:38 - Loading AI models...
2025-09-20 19:40:56,926 - models.lstm_health_model - ERROR - lstm_health_model.py:338 - Error loading model: [Errno 2] Unable to synchronously open file (unable to open file: name = './models/lstm_health_model.h5', errno = 2, error message = 'No such file or directory', flags = 0, o_flags = 0)
2025-09-20 19:40:56,926 - models.ai_models - WARNING - ai_models.py:64 - Could not load LSTM model: [Errno 2] Unable to synchronously open file (unable to open file: name = './models/lstm_health_model.h5', errno = 2, error message = 'No such file or directory', flags = 0, o_flags = 0). Will need training.
2025-09-20 19:40:56,926 - models.transformer_genomic_model - ERROR - transformer_genomic_model.py:418 - Error loading model: [Errno 2] Unable to synchronously open file (unable to open file: name = './models/transformer_genomic_model.h5', errno = 2, error message = 'No such file or directory', flags = 0, o_flags = 0)
2025-09-20 19:40:56,928 - models.ai_models - WARNING - ai_models.py:70 - Could not load Transformer model: [Errno 2] Unable to synchronously open file (unable to open file: name = './models/transformer_genomic_model.h5', errno = 2, error message = 'No such file or directory', flags = 0, o_flags = 0). Will need training.
2025-09-20 19:40:56,928 - models.ai_models - INFO - ai_models.py:90 - Model loading completed
2025-09-20 19:40:56,928 - __main__ - INFO - train_models.py:275 - Starting model training...
2025-09-20 19:40:56,928 - models.ai_models - INFO - ai_models.py:119 - Starting comprehensive model training...
2025-09-20 19:40:56,929 - models.ai_models - INFO - ai_models.py:122 - Training LSTM health model...
2025-09-20 19:40:56,948 - models.ai_models - INFO - ai_models.py:132 - Prepared training data with 2000 samples
2025-09-20 19:40:56,949 - models.lstm_health_model - INFO - lstm_health_model.py:217 - Preparing training data...
2025-09-20 19:40:56,949 - models.lstm_health_model - INFO - lstm_health_model.py:147 - Training data shape: (2000, 17)
2025-09-20 19:40:56,949 - models.lstm_health_model - INFO - lstm_health_model.py:148 - Feature columns: ['age', 'gender', 'height', 'weight', 'bmi', 'cholesterol_total', 'cholesterol_hdl', 'cholesterol_ldl', 'blood_pressure_systolic', 'blood_pressure_diastolic', 'glucose', 'triglycerides']
2025-09-20 19:40:56,949 - models.lstm_health_model - INFO - lstm_health_model.py:149 - Target columns: ['nutrition_category', 'health_risk', 'metabolic_rate', 'caloric_needs']
2025-09-20 19:40:56,950 - models.lstm_health_model - INFO - lstm_health_model.py:150 - Has timestamp: False
2025-09-20 19:40:57,037 - models.lstm_health_model - INFO - lstm_health_model.py:184 - Created 2000 sequences
2025-09-20 19:40:57,040 - models.lstm_health_model - INFO - lstm_health_model.py:190 - Final X_sequences shape: (2000, 30, 12)
2025-09-20 19:40:57,279 - models.lstm_health_model - INFO - lstm_health_model.py:225 - Model architecture:
None
2025-09-20 19:40:57,279 - models.lstm_health_model - INFO - lstm_health_model.py:234 - Starting model training...
2025-09-20 19:41:31,305 - models.lstm_health_model - INFO - lstm_health_model.py:245 - Model training completed!
2025-09-20 19:41:31,306 - absl - WARNING - saving_api.py:83 - You are saving your model as an HDF5 file via `model.save()` or `keras.saving.save_model(model)`. This file format is considered legacy. We recommend using instead the native Keras format, e.g. `model.save('my_model.keras')` or `keras.saving.save_model(model, 'my_model.keras')`. 
2025-09-20 19:41:31,386 - models.lstm_health_model - INFO - lstm_health_model.py:314 - Model saved to ./models/lstm_health_model
2025-09-20 19:41:31,386 - models.ai_models - INFO - ai_models.py:149 - Training Transformer genomic model...
2025-09-20 19:41:31,386 - models.transformer_genomic_model - INFO - transformer_genomic_model.py:285 - Preprocessing genomic data...
2025-09-20 19:41:32,228 - models.transformer_genomic_model - INFO - transformer_genomic_model.py:293 - Model architecture:
None
2025-09-20 19:41:32,228 - models.transformer_genomic_model - INFO - transformer_genomic_model.py:302 - Starting model training...
2025-09-20 19:41:33,245 - models.ai_models - ERROR - ai_models.py:200 - Error during training: Arguments `target` and `output` must have the same rank (ndim). Received: target.shape=(32,), output.shape=(32, 6)
2025-09-20 19:41:33,245 - __main__ - ERROR - train_models.py:293 - Error during model training: Arguments `target` and `output` must have the same rank (ndim). Received: target.shape=(32,), output.shape=(32, 6)
2025-09-20 19:44:19,961 - __main__ - INFO - train_models.py:244 - Starting AI Model Training for Diet Recommendation System
2025-09-20 19:44:19,962 - __main__ - INFO - train_models.py:248 - Generating synthetic training data...
2025-09-20 19:44:19,962 - __main__ - INFO - train_models.py:39 - Generating health data for 2000 users...
2025-09-20 19:44:21,906 - __main__ - INFO - train_models.py:95 - Generated 119969 health data points
2025-09-20 19:44:21,929 - __main__ - INFO - train_models.py:100 - Generating genomic data for 2000 users...
2025-09-20 19:44:22,234 - __main__ - INFO - train_models.py:134 - Generated genomic data for 2000 users
2025-09-20 19:44:22,235 - __main__ - INFO - train_models.py:139 - Generating mental health data for 2000 users...
2025-09-20 19:44:22,284 - __main__ - INFO - train_models.py:166 - Generated mental health data for 2000 users
2025-09-20 19:44:22,284 - __main__ - INFO - train_models.py:172 - Generating nutrition labels...
2025-09-20 19:44:32,933 - __main__ - INFO - train_models.py:239 - Generated labels for 2000 users
2025-09-20 19:44:34,331 - __main__ - INFO - train_models.py:267 - Training datasets saved successfully
2025-09-20 19:44:34,332 - __main__ - INFO - train_models.py:270 - Initializing AI Model Manager...
2025-09-20 19:44:34,332 - models.ai_models - INFO - ai_models.py:38 - Loading AI models...
2025-09-20 19:44:34,521 - models.lstm_health_model - ERROR - lstm_health_model.py:338 - Error loading model: Could not deserialize 'keras.metrics.mse' because it is not a KerasSaveable subclass
2025-09-20 19:44:34,522 - models.ai_models - WARNING - ai_models.py:64 - Could not load LSTM model: Could not deserialize 'keras.metrics.mse' because it is not a KerasSaveable subclass. Will need training.
2025-09-20 19:44:34,523 - models.transformer_genomic_model - ERROR - transformer_genomic_model.py:418 - Error loading model: [Errno 2] Unable to synchronously open file (unable to open file: name = './models/transformer_genomic_model.h5', errno = 2, error message = 'No such file or directory', flags = 0, o_flags = 0)
2025-09-20 19:44:34,523 - models.ai_models - WARNING - ai_models.py:70 - Could not load Transformer model: [Errno 2] Unable to synchronously open file (unable to open file: name = './models/transformer_genomic_model.h5', errno = 2, error message = 'No such file or directory', flags = 0, o_flags = 0). Will need training.
2025-09-20 19:44:34,523 - models.ai_models - INFO - ai_models.py:90 - Model loading completed
2025-09-20 19:44:34,524 - __main__ - INFO - train_models.py:275 - Starting model training...
2025-09-20 19:44:34,524 - models.ai_models - INFO - ai_models.py:119 - Starting comprehensive model training...
2025-09-20 19:44:34,524 - models.ai_models - INFO - ai_models.py:122 - Training LSTM health model...
2025-09-20 19:44:34,542 - models.ai_models - INFO - ai_models.py:132 - Prepared training data with 2000 samples
2025-09-20 19:44:34,542 - models.lstm_health_model - INFO - lstm_health_model.py:217 - Preparing training data...
2025-09-20 19:44:34,543 - models.lstm_health_model - INFO - lstm_health_model.py:147 - Training data shape: (2000, 17)
2025-09-20 19:44:34,543 - models.lstm_health_model - INFO - lstm_health_model.py:148 - Feature columns: ['age', 'gender', 'height', 'weight', 'bmi', 'cholesterol_total', 'cholesterol_hdl', 'cholesterol_ldl', 'blood_pressure_systolic', 'blood_pressure_diastolic', 'glucose', 'triglycerides']
2025-09-20 19:44:34,544 - models.lstm_health_model - INFO - lstm_health_model.py:149 - Target columns: ['nutrition_category', 'health_risk', 'metabolic_rate', 'caloric_needs']
2025-09-20 19:44:34,544 - models.lstm_health_model - INFO - lstm_health_model.py:150 - Has timestamp: False
2025-09-20 19:44:34,629 - models.lstm_health_model - INFO - lstm_health_model.py:184 - Created 2000 sequences
2025-09-20 19:44:34,631 - models.lstm_health_model - INFO - lstm_health_model.py:190 - Final X_sequences shape: (2000, 30, 12)
2025-09-20 19:44:34,788 - models.lstm_health_model - INFO - lstm_health_model.py:225 - Model architecture:
None
2025-09-20 19:44:34,789 - models.lstm_health_model - INFO - lstm_health_model.py:234 - Starting model training...
2025-09-20 19:45:09,373 - models.lstm_health_model - INFO - lstm_health_model.py:245 - Model training completed!
2025-09-20 19:45:09,374 - absl - WARNING - saving_api.py:83 - You are saving your model as an HDF5 file via `model.save()` or `keras.saving.save_model(model)`. This file format is considered legacy. We recommend using instead the native Keras format, e.g. `model.save('my_model.keras')` or `keras.saving.save_model(model, 'my_model.keras')`. 
2025-09-20 19:45:09,447 - models.lstm_health_model - INFO - lstm_health_model.py:314 - Model saved to ./models/lstm_health_model
2025-09-20 19:45:09,448 - models.ai_models - INFO - ai_models.py:149 - Training Transformer genomic model...
2025-09-20 19:45:09,448 - models.transformer_genomic_model - INFO - transformer_genomic_model.py:285 - Preprocessing genomic data...
2025-09-20 19:45:10,314 - models.transformer_genomic_model - INFO - transformer_genomic_model.py:293 - Model architecture:
None
2025-09-20 19:45:10,314 - models.transformer_genomic_model - INFO - transformer_genomic_model.py:302 - Starting model training...
2025-09-20 20:04:41,827 - __main__ - INFO - train_models.py:244 - Starting AI Model Training for Diet Recommendation System
2025-09-20 20:04:41,828 - __main__ - INFO - train_models.py:248 - Generating synthetic training data...
2025-09-20 20:04:41,828 - __main__ - INFO - train_models.py:39 - Generating health data for 2000 users...
2025-09-20 20:04:43,488 - __main__ - INFO - train_models.py:95 - Generated 119969 health data points
2025-09-20 20:04:43,505 - __main__ - INFO - train_models.py:100 - Generating genomic data for 2000 users...
2025-09-20 20:04:43,853 - __main__ - INFO - train_models.py:134 - Generated genomic data for 2000 users
2025-09-20 20:04:43,854 - __main__ - INFO - train_models.py:139 - Generating mental health data for 2000 users...
2025-09-20 20:04:43,895 - __main__ - INFO - train_models.py:166 - Generated mental health data for 2000 users
2025-09-20 20:04:43,896 - __main__ - INFO - train_models.py:172 - Generating nutrition labels...
2025-09-20 20:04:53,752 - __main__ - INFO - train_models.py:239 - Generated labels for 2000 users
2025-09-20 20:04:55,094 - __main__ - INFO - train_models.py:267 - Training datasets saved successfully
2025-09-20 20:04:55,095 - __main__ - INFO - train_models.py:270 - Initializing AI Model Manager...
2025-09-20 20:04:55,095 - models.ai_models - INFO - ai_models.py:38 - Loading AI models...
2025-09-20 20:04:55,349 - models.lstm_health_model - ERROR - lstm_health_model.py:338 - Error loading model: Could not deserialize 'keras.metrics.mse' because it is not a KerasSaveable subclass
2025-09-20 20:04:55,350 - models.ai_models - WARNING - ai_models.py:64 - Could not load LSTM model: Could not deserialize 'keras.metrics.mse' because it is not a KerasSaveable subclass. Will need training.
2025-09-20 20:04:55,351 - models.transformer_genomic_model - ERROR - transformer_genomic_model.py:418 - Error loading model: [Errno 2] Unable to synchronously open file (unable to open file: name = './models/transformer_genomic_model.h5', errno = 2, error message = 'No such file or directory', flags = 0, o_flags = 0)
2025-09-20 20:04:55,351 - models.ai_models - WARNING - ai_models.py:70 - Could not load Transformer model: [Errno 2] Unable to synchronously open file (unable to open file: name = './models/transformer_genomic_model.h5', errno = 2, error message = 'No such file or directory', flags = 0, o_flags = 0). Will need training.
2025-09-20 20:04:55,352 - models.ai_models - INFO - ai_models.py:90 - Model loading completed
2025-09-20 20:04:55,352 - __main__ - INFO - train_models.py:275 - Starting model training...
2025-09-20 20:04:55,352 - models.ai_models - INFO - ai_models.py:119 - Starting comprehensive model training...
2025-09-20 20:04:55,352 - models.ai_models - INFO - ai_models.py:122 - Training LSTM health model...
2025-09-20 20:04:55,367 - models.ai_models - INFO - ai_models.py:132 - Prepared training data with 2000 samples
2025-09-20 20:04:55,368 - models.lstm_health_model - INFO - lstm_health_model.py:217 - Preparing training data...
2025-09-20 20:04:55,368 - models.lstm_health_model - INFO - lstm_health_model.py:147 - Training data shape: (2000, 17)
2025-09-20 20:04:55,368 - models.lstm_health_model - INFO - lstm_health_model.py:148 - Feature columns: ['age', 'gender', 'height', 'weight', 'bmi', 'cholesterol_total', 'cholesterol_hdl', 'cholesterol_ldl', 'blood_pressure_systolic', 'blood_pressure_diastolic', 'glucose', 'triglycerides']
2025-09-20 20:04:55,368 - models.lstm_health_model - INFO - lstm_health_model.py:149 - Target columns: ['nutrition_category', 'health_risk', 'metabolic_rate', 'caloric_needs']
2025-09-20 20:04:55,368 - models.lstm_health_model - INFO - lstm_health_model.py:150 - Has timestamp: False
2025-09-20 20:04:55,442 - models.lstm_health_model - INFO - lstm_health_model.py:184 - Created 2000 sequences
2025-09-20 20:04:55,446 - models.lstm_health_model - INFO - lstm_health_model.py:190 - Final X_sequences shape: (2000, 30, 12)
2025-09-20 20:04:55,524 - models.lstm_health_model - INFO - lstm_health_model.py:225 - Model architecture:
None
2025-09-20 20:04:55,524 - models.lstm_health_model - INFO - lstm_health_model.py:234 - Starting model training...
2025-09-20 20:05:59,879 - models.lstm_health_model - INFO - lstm_health_model.py:245 - Model training completed!
2025-09-20 20:05:59,880 - absl - WARNING - saving_api.py:83 - You are saving your model as an HDF5 file via `model.save()` or `keras.saving.save_model(model)`. This file format is considered legacy. We recommend using instead the native Keras format, e.g. `model.save('my_model.keras')` or `keras.saving.save_model(model, 'my_model.keras')`. 
2025-09-20 20:05:59,946 - models.lstm_health_model - INFO - lstm_health_model.py:314 - Model saved to ./models/lstm_health_model
2025-09-20 20:05:59,946 - models.ai_models - INFO - ai_models.py:149 - Training Transformer genomic model...
2025-09-20 20:05:59,947 - models.transformer_genomic_model - INFO - transformer_genomic_model.py:285 - Preprocessing genomic data...
2025-09-20 20:06:00,765 - models.transformer_genomic_model - INFO - transformer_genomic_model.py:293 - Model architecture:
None
2025-09-20 20:06:00,766 - models.transformer_genomic_model - INFO - transformer_genomic_model.py:302 - Starting model training...
2025-09-20 20:15:29,829 - __main__ - INFO - train_models.py:244 - Starting AI Model Training for Diet Recommendation System
2025-09-20 20:15:29,830 - __main__ - INFO - train_models.py:248 - Generating synthetic training data...
2025-09-20 20:15:29,830 - __main__ - INFO - train_models.py:39 - Generating health data for 2000 users...
2025-09-20 20:15:31,495 - __main__ - INFO - train_models.py:95 - Generated 119969 health data points
2025-09-20 20:15:31,513 - __main__ - INFO - train_models.py:100 - Generating genomic data for 2000 users...
2025-09-20 20:15:31,812 - __main__ - INFO - train_models.py:134 - Generated genomic data for 2000 users
2025-09-20 20:15:31,813 - __main__ - INFO - train_models.py:139 - Generating mental health data for 2000 users...
2025-09-20 20:15:31,854 - __main__ - INFO - train_models.py:166 - Generated mental health data for 2000 users
2025-09-20 20:15:31,855 - __main__ - INFO - train_models.py:172 - Generating nutrition labels...
2025-09-20 20:15:42,616 - __main__ - INFO - train_models.py:239 - Generated labels for 2000 users
2025-09-20 20:15:43,976 - __main__ - INFO - train_models.py:267 - Training datasets saved successfully
2025-09-20 20:15:43,977 - __main__ - INFO - train_models.py:270 - Initializing AI Model Manager...
2025-09-20 20:15:43,977 - models.ai_models - INFO - ai_models.py:38 - Loading AI models...
2025-09-20 20:15:44,226 - models.lstm_health_model - ERROR - lstm_health_model.py:338 - Error loading model: Could not deserialize 'keras.metrics.mse' because it is not a KerasSaveable subclass
2025-09-20 20:15:44,226 - models.ai_models - WARNING - ai_models.py:64 - Could not load LSTM model: Could not deserialize 'keras.metrics.mse' because it is not a KerasSaveable subclass. Will need training.
2025-09-20 20:15:44,227 - models.transformer_genomic_model - ERROR - transformer_genomic_model.py:418 - Error loading model: [Errno 2] Unable to synchronously open file (unable to open file: name = './models/transformer_genomic_model.h5', errno = 2, error message = 'No such file or directory', flags = 0, o_flags = 0)
2025-09-20 20:15:44,228 - models.ai_models - WARNING - ai_models.py:70 - Could not load Transformer model: [Errno 2] Unable to synchronously open file (unable to open file: name = './models/transformer_genomic_model.h5', errno = 2, error message = 'No such file or directory', flags = 0, o_flags = 0). Will need training.
2025-09-20 20:15:44,228 - models.ai_models - INFO - ai_models.py:90 - Model loading completed
2025-09-20 20:15:44,228 - __main__ - INFO - train_models.py:275 - Starting model training...
2025-09-20 20:15:44,228 - models.ai_models - INFO - ai_models.py:119 - Starting comprehensive model training...
2025-09-20 20:15:44,228 - models.ai_models - INFO - ai_models.py:122 - Training LSTM health model...
2025-09-20 20:15:44,246 - models.ai_models - INFO - ai_models.py:132 - Prepared training data with 2000 samples
2025-09-20 20:15:44,247 - models.lstm_health_model - INFO - lstm_health_model.py:217 - Preparing training data...
2025-09-20 20:15:44,247 - models.lstm_health_model - INFO - lstm_health_model.py:147 - Training data shape: (2000, 17)
2025-09-20 20:15:44,247 - models.lstm_health_model - INFO - lstm_health_model.py:148 - Feature columns: ['age', 'gender', 'height', 'weight', 'bmi', 'cholesterol_total', 'cholesterol_hdl', 'cholesterol_ldl', 'blood_pressure_systolic', 'blood_pressure_diastolic', 'glucose', 'triglycerides']
2025-09-20 20:15:44,247 - models.lstm_health_model - INFO - lstm_health_model.py:149 - Target columns: ['nutrition_category', 'health_risk', 'metabolic_rate', 'caloric_needs']
2025-09-20 20:15:44,248 - models.lstm_health_model - INFO - lstm_health_model.py:150 - Has timestamp: False
2025-09-20 20:15:44,322 - models.lstm_health_model - INFO - lstm_health_model.py:184 - Created 2000 sequences
2025-09-20 20:15:44,325 - models.lstm_health_model - INFO - lstm_health_model.py:190 - Final X_sequences shape: (2000, 30, 12)
2025-09-20 20:15:44,400 - models.lstm_health_model - INFO - lstm_health_model.py:225 - Model architecture:
None
2025-09-20 20:15:44,401 - models.lstm_health_model - INFO - lstm_health_model.py:234 - Starting model training...
2025-09-20 20:17:54,965 - models.lstm_health_model - INFO - lstm_health_model.py:245 - Model training completed!
2025-09-20 20:17:54,967 - absl - WARNING - saving_api.py:83 - You are saving your model as an HDF5 file via `model.save()` or `keras.saving.save_model(model)`. This file format is considered legacy. We recommend using instead the native Keras format, e.g. `model.save('my_model.keras')` or `keras.saving.save_model(model, 'my_model.keras')`. 
2025-09-20 20:17:55,102 - models.lstm_health_model - INFO - lstm_health_model.py:314 - Model saved to ./models/lstm_health_model
2025-09-20 20:17:55,104 - models.ai_models - INFO - ai_models.py:149 - Training Transformer genomic model...
2025-09-20 20:17:55,104 - models.transformer_genomic_model - INFO - transformer_genomic_model.py:285 - Preprocessing genomic data...
2025-09-20 20:17:56,573 - models.transformer_genomic_model - INFO - transformer_genomic_model.py:293 - Model architecture:
None
2025-09-20 20:17:56,573 - models.transformer_genomic_model - INFO - transformer_genomic_model.py:302 - Starting model training...
2025-09-20 20:53:36,609 - __main__ - INFO - train_models.py:244 - Starting AI Model Training for Diet Recommendation System
2025-09-20 20:53:36,609 - __main__ - INFO - train_models.py:248 - Generating synthetic training data...
2025-09-20 20:53:36,609 - __main__ - INFO - train_models.py:39 - Generating health data for 2000 users...
2025-09-20 20:53:38,782 - __main__ - INFO - train_models.py:95 - Generated 119969 health data points
2025-09-20 20:53:38,808 - __main__ - INFO - train_models.py:100 - Generating genomic data for 2000 users...
2025-09-20 20:53:39,256 - __main__ - INFO - train_models.py:134 - Generated genomic data for 2000 users
2025-09-20 20:53:39,257 - __main__ - INFO - train_models.py:139 - Generating mental health data for 2000 users...
2025-09-20 20:53:39,331 - __main__ - INFO - train_models.py:166 - Generated mental health data for 2000 users
2025-09-20 20:53:39,333 - __main__ - INFO - train_models.py:172 - Generating nutrition labels...
2025-09-20 20:54:00,051 - __main__ - INFO - train_models.py:239 - Generated labels for 2000 users
2025-09-20 20:54:03,501 - __main__ - INFO - train_models.py:267 - Training datasets saved successfully
2025-09-20 20:54:03,501 - __main__ - INFO - train_models.py:270 - Initializing AI Model Manager...
2025-09-20 20:54:03,501 - models.ai_models - INFO - ai_models.py:38 - Loading AI models...
2025-09-20 20:54:03,923 - models.lstm_health_model - ERROR - lstm_health_model.py:338 - Error loading model: Could not deserialize 'keras.metrics.mse' because it is not a KerasSaveable subclass
2025-09-20 20:54:03,925 - models.ai_models - WARNING - ai_models.py:64 - Could not load LSTM model: Could not deserialize 'keras.metrics.mse' because it is not a KerasSaveable subclass. Will need training.
2025-09-20 20:54:03,926 - models.transformer_genomic_model - ERROR - transformer_genomic_model.py:418 - Error loading model: [Errno 2] Unable to synchronously open file (unable to open file: name = './models/transformer_genomic_model.h5', errno = 2, error message = 'No such file or directory', flags = 0, o_flags = 0)
2025-09-20 20:54:03,926 - models.ai_models - WARNING - ai_models.py:70 - Could not load Transformer model: [Errno 2] Unable to synchronously open file (unable to open file: name = './models/transformer_genomic_model.h5', errno = 2, error message = 'No such file or directory', flags = 0, o_flags = 0). Will need training.
2025-09-20 20:54:03,926 - models.ai_models - INFO - ai_models.py:90 - Model loading completed
2025-09-20 20:54:03,926 - __main__ - INFO - train_models.py:275 - Starting model training...
2025-09-20 20:54:03,928 - models.ai_models - INFO - ai_models.py:119 - Starting comprehensive model training...
2025-09-20 20:54:03,928 - models.ai_models - INFO - ai_models.py:122 - Training LSTM health model...
2025-09-20 20:54:03,949 - models.ai_models - INFO - ai_models.py:132 - Prepared training data with 2000 samples
2025-09-20 20:54:03,950 - models.lstm_health_model - INFO - lstm_health_model.py:217 - Preparing training data...
2025-09-20 20:54:03,950 - models.lstm_health_model - INFO - lstm_health_model.py:147 - Training data shape: (2000, 17)
2025-09-20 20:54:03,950 - models.lstm_health_model - INFO - lstm_health_model.py:148 - Feature columns: ['age', 'gender', 'height', 'weight', 'bmi', 'cholesterol_total', 'cholesterol_hdl', 'cholesterol_ldl', 'blood_pressure_systolic', 'blood_pressure_diastolic', 'glucose', 'triglycerides']
2025-09-20 20:54:03,950 - models.lstm_health_model - INFO - lstm_health_model.py:149 - Target columns: ['nutrition_category', 'health_risk', 'metabolic_rate', 'caloric_needs']
2025-09-20 20:54:03,951 - models.lstm_health_model - INFO - lstm_health_model.py:150 - Has timestamp: False
2025-09-20 20:54:04,056 - models.lstm_health_model - INFO - lstm_health_model.py:184 - Created 2000 sequences
2025-09-20 20:54:04,059 - models.lstm_health_model - INFO - lstm_health_model.py:190 - Final X_sequences shape: (2000, 30, 12)
2025-09-20 20:54:04,162 - models.lstm_health_model - INFO - lstm_health_model.py:225 - Model architecture:
None
2025-09-20 20:54:04,164 - models.lstm_health_model - INFO - lstm_health_model.py:234 - Starting model training...
2025-09-20 20:57:39,695 - models.lstm_health_model - INFO - lstm_health_model.py:245 - Model training completed!
2025-09-20 20:57:39,698 - absl - WARNING - saving_api.py:83 - You are saving your model as an HDF5 file via `model.save()` or `keras.saving.save_model(model)`. This file format is considered legacy. We recommend using instead the native Keras format, e.g. `model.save('my_model.keras')` or `keras.saving.save_model(model, 'my_model.keras')`. 
2025-09-20 20:57:39,894 - models.lstm_health_model - INFO - lstm_health_model.py:314 - Model saved to ./models/lstm_health_model
2025-09-20 20:57:39,898 - models.ai_models - INFO - ai_models.py:149 - Training Transformer genomic model...
2025-09-20 20:57:39,901 - models.transformer_genomic_model - INFO - transformer_genomic_model.py:285 - Preprocessing genomic data...
2025-09-20 20:57:42,319 - models.transformer_genomic_model - INFO - transformer_genomic_model.py:293 - Model architecture:
None
2025-09-20 20:57:42,322 - models.transformer_genomic_model - INFO - transformer_genomic_model.py:302 - Starting model training...
